Workbook

Sheet Leia-me
A1: MODELO DE CUSTOS E PRECIFICACAO — Protocolo de Emagrecimento
A3: Supplements LLC · funil de webinar ao vivo com recuperacao comercial · mercado EUA · oferta: 6 meses de tratamento + 3 meses de brinde · preco-alvo $389
A5: COMO USAR
A6: 1. Preencha a aba PREMISSAS. Toda celula AMARELA com texto AZUL e campo seu para editar.
A7: 2. As demais abas sao formula e recalculam sozinhas.
A8: 3. Quando os orcamentos chegarem, troque os custos no bloco 1 de PREMISSAS. E o que mais move o resultado.
A9: 4. OFERTA compara o que fazer com os meses 4 a 6 do po: dar, ou vender como bump.
A10: 5. TETO_COGS responde a pergunta inversa: dado o preco, quanto o produto PODE custar.
A12: CORES: azul sobre amarelo = premissa editavel · preto = formula · verde = puxado de outra aba
A14: ABAS
A15: PREMISSAS — custos de produto, logistica, funil, midia, comercial, taxas, precos.
A16: CUSTOS — monta o custo de um pedido e o capital de estoque por tamanho de lote.
... A28: As taxas de funil sao referencias de mercado. Substitua pelos dados reais apos o primeiro webinar.

Sheet Premissas
A1: PREMISSAS
A3: 1. CUSTO UNITARIO DO PRODUTO (FOB fabricante, com frasco e rotulo)
A4: Principal — frasco 60 caps (30 dias) | B4: 14 | D4: SUBSTITUIR pela cotacao. Ativos de marca em dose clinica.
A5: Brinde — po 30 dias | B5: 6 | D5: SUBSTITUIR. Cotar tambem pote de 60 dias.
A6: Bump Glicemico — frasco 60 caps | B6: 4.5 | D6: SUBSTITUIR.
A7: Bump Acelerador — frasco 60 caps | B7: 4.5 | D7: SUBSTITUIR.
A8: Frete de entrada por unidade | B8: 0.4 | D8: Fabrica -> 3PL, rateado.
A10: 2. COMPOSICAO DO PEDIDO (envio unico de 6 meses)
A11: Unidades do principal por pedido | B11: 6 | D11: 6 frascos = 180 dias.
A12: Unidades do brinde incluidas gratis | B12: 3 | D12: DEFINIDO: 6 meses de tratamento + 3 meses de brinde.
A13: Unidades do bump glicemico | B13: 3
A14: Unidades do bump acelerador | B14: 3
A15: Take rate do bump glicemico | B15: 0.35
A16: Take rate do bump acelerador | B16: 0.25
A18: 3. LOGISTICA E ATENDIMENTO
A19: Caixa de envio + inserto | B19: 3
A20: 3PL — picking e packing por pedido | B20: 3.5 | D20: Confirmar com o 3PL.
A21: Frete ao cliente — base | B21: 9 | D21: PEDIR AO 3PL. Caixa, nao envelope.
A22: Frete ao cliente — adicional por unidade | B22: 0.6 | D22: Peso e volume crescem com a quantidade de frascos.
A23: Armazenagem por pedido (rateio) | B23: 1.2
A24: Suporte ao cliente por pedido | B24: 3 | D24: Consumo de 6 meses gera mais ticket que 30 dias.
A26: 4. FUNIL — WEBINAR AO VIVO 20h
A27: Verba de midia no mes | B27: 30000
A28: CPL — custo por inscricao | B28: 5 | D28: Emagrecimento EUA. Medir e substituir.
A29: Taxa de confirmacao no CRM | B29: 0.6
A30: Taxa de presenca (sobre inscritos) | B30: 0.42 | D30: Horario marcado tem show rate baixo.
A31: Fica ate o pitch (1h15) | B31: 0.58 | D31: Sobre quem entrou na aula.
A32: Conversao no checkout (sobre quem viu o pitch) | B32: 0.1 | D32: ALAVANCA MAIS SENSIVEL DO MODELO.
A33: Uplift do time comercial na recuperacao | B33: 0.5 | D33: Vendas adicionais sobre o checkout automatico.
A34: Custo mensal de CRM, e-mail, SMS e WhatsApp | B34: 1500
A36: 5. TIME COMERCIAL (recuperacao por temperatura)
A37: Custo fixo mensal da equipe | B37: 9000
A38: Comissao sobre a receita recuperada | B38: 0.1 | D38: Somente sobre o que o comercial fecha.
A40: 6. PRECOS DA OFERTA
A41: Oferta principal — 6 meses | B41: 389 | D41: Preco-alvo definido.
A42: Bump glicemico — 3 meses | B42: 97
A43: Bump acelerador — 3 meses | B43: 97
A44: Bump do po (meses 4-6) — preco | B44: 79 | D44: Meses do po nao incluidos, vendidos no checkout.
A45: Bump do po — take rate | B45: 0.4
A46: MARGEM LIQUIDA ALVO | B46: 0.3 | D46: Meta do negocio. Usada nas abas TETO_COGS e GRADE.
...

Sheet Custos
A1: CUSTO DE UM PEDIDO
A3: PACOTE BASE — 6 meses do principal + brinde incluido
A4: Item | B4: Unid./pedido | C4: Custo unit. | D4: Total
A5: Principal (60 caps) | B5: =Premissas!$B$11 | C5: =Premissas!$B$4 | D5: =B5*C5
A6: Brinde (po) incluido gratis | B6: =Premissas!$B$12 | C6: =Premissas!$B$5 | D6: =B6*C6
A7: Brinde (po) vendido no bump | B7: =Premissas!$B$45*(Premissas!$B$11-Premissas!$B$12) | C7: =Premissas!$B$5 | D7: =B7*C7
A8: Frete de entrada | B8: =SUM(B5:B7) | C8: =Premissas!$B$8 | D8: =B8*C8
A9: Produto do pacote base | D9: =SUM(D5:D8)
A11: BUMPS — custo esperado por pedido (ponderado pelo take rate)
A12: Item | B12: Unid. se levado | C12: Custo se levado | D12: Esperado/pedido
A13: Bump Glicemico | B13: =Premissas!$B$13 | C13: =B13*(Premissas!$B$6+Premissas!$B$8) | D13: =C13*Premissas!$B$15
A14: Bump Acelerador | B14: =Premissas!$B$14 | C14: =B14*(Premissas!$B$7+Premissas!$B$8) | D14: =C14*Premissas!$B$16
A15: Bumps esperados por pedido | D15: =SUM(D13:D14)
A17: CUSTO TOTAL POR PEDIDO
A18: Produto (base + bumps esperados) | D18: =$D$9+$D$15
A19: Caixa e inserto | D19: =Premissas!$B$19
A20: 3PL picking e packing | D20: =Premissas!$B$20
A21: Frete ao cliente | D21: =Premissas!$B$21+Custos!$B$8*Premissas!$B$22
A22: Armazenagem (rateio) | D22: =Premissas!$B$23
A23: Suporte ao cliente | D23: =Premissas!$B$24
A24: CUSTO TOTAL DE ENTREGA POR PEDIDO | D24: =SUM(D18:D23)
A26: Produto como % do preco da oferta | D26: =Custos!$D$18/Premissas!$B$41 | E26: Referencia do mercado de resposta direta: produto + logistica em 20-25% do preco.
A28: CAPITAL DE ESTOQUE — quantos clientes um lote atende
A29: Lote (un. do principal) | B29: Clientes atendidos | C29: Capital no principal | D29: Capital total do pacote
A30: 1000 | B30: =A30/Premissas!$B$11 | C30: =A30*Premissas!$B$4 | D30: =B30*($D$9+$D$15) | E30: Coluna A editavel. Cada cliente consome 6 unidades do principal:
A31: 3000 | B31: =A31/Premissas!$B$11 | C31: =A31*Premissas!$B$4 | D31: =B31*($D$9+$D$15) | E31: cote pensando em CLIENTES, nao em unidades. 5.000 un. = ~830 clientes.
A32: 6000 | B32: =A32/Premissas!$B$11 | C32: =A32*Premissas!$B$4 | D32: =B32*($D$9+$D$15)
A33: 12000 | B33: =A33/Premissas!$B$11 | C33: =A33*Premissas!$B$4 | D33: =B33*($D$9+$D$15)

Sheet Funil
A1: FUNIL DO WEBINAR AO VIVO — VOLUME MENSAL
A3: ETAPAS
A4: Verba de midia | B4: =Premissas!$B$27
A5: Inscricoes na aula | B5: =Premissas!$B$27/Premissas!$B$28
A6: Confirmaram no CRM | B6: =$B$5*Premissas!$B$29
A7: Entraram na aula | B7: =$B$5*Premissas!$B$30
A8: Ficaram ate o pitch (1h15) | B8: =$B$7*Premissas!$B$31
A9: Pedidos no checkout (automatico) | B9: =$B$8*Premissas!$B$32
A10: Pedidos recuperados pelo comercial | B10: =$B$9*Premissas!$B$33
A11: PEDIDOS PAGOS NO MES | B11: =$B$9+$B$10
A13: INDICADORES DE AQUISICAO
A14: Ticket medio por pedido | B14: =PnL!$B$3
A15: Receita bruta no mes | B15: =Funil!$B$11*Funil!$B$14
A16: CAC — custo de aquisicao por pedido | B16: =Premissas!$B$27/Funil!$B$11 | D16: Comparar com o CAC MAXIMO na aba PNL. Acima dele, o funil nao paga.
A17: ROAS bruto | B17: =Funil!$B$15/Premissas!$B$27
A18: Conversao inscrito -> pedido | B18: =Funil!$B$11/$B$5
A19: Custo por participante da aula | B19: =Premissas!$B$27/$B$7
A21: A recuperacao comercial trabalha do mais quente para o mais frio: erro de cartao, checkout aberto sem
A22: preencher, clicou no link, ficou ate o fim sem clicar, assistiu metade. Cada faixa tem taxa propria —
A23: quando houver dado real, abrir esta linha em cinco e medir cada uma separado.

Sheet PnL
A1: RESULTADO POR PEDIDO
B2: Venda direta | C2: Afiliado
A3: Receita bruta media por pedido | B3: =Premissas!$B$41+Premissas!$B$42*Premissas!$B$15+Premissas!$B$43*Premissas!$B$16+Premissas!$B$44*Premissas!$B$45 | C3: =Premissas!$B$41+Premissas!$B$42*Premissas!$B$15+Premissas!$B$43*Premissas!$B$16+Premissas!$B$44*Premissas!$B$45
A4: (-) Reembolsos | B4: =-$B$3*Premissas!$B$51 | C4: =-$C$3*Premissas!$B$60
A5: (-) Chargebacks (receita perdida) | B5: =-$B$3*Premissas!$B$52 | C5: =-$C$3*Premissas!$B$52
A6: (-) Multa de chargeback | B6: =-Premissas!$B$53*Premissas!$B$52 | C6: =-Premissas!$B$53*Premissas!$B$52
A7: (=) Receita liquida | B7: =SUM(B3:B6) | C7: =SUM(C3:C6)
A9: (-) Produto (COGS) | B9: =-Custos!$D$18 | C9: =-Custos!$D$18
A10: (-) Embalagem, 3PL, frete, armazenagem, suporte | B10: =-(Custos!$D$24-Custos!$D$18) | C10: =-(Custos!$D$24-Custos!$D$18)
A11: (-) Processamento / plataforma | B11: =-($B$3*Premissas!$B$49+Premissas!$B$50) | C11: =-($C$3*Premissas!$B$57+Premissas!$B$58)
A12: (=) Margem de contribuicao (antes de aquisicao) | B12: =$B$7+SUM(B9:B11) | C12: =$C$7+SUM(C9:C11)
A14: (-) Midia / comissao do afiliado | B14: =-Funil!$B$16 | C14: =-$C$7*Premissas!$B$59
A15: (-) Comercial: comissao sobre recuperado | B15: =-$B$3*Premissas!$B$38*(Funil!$B$10/Funil!$B$11) | C15: =0
A16: (-) Comercial: custo fixo rateado | B16: =-Premissas!$B$37/Funil!$B$11 | C16: =0
A17: (-) CRM, e-mail, SMS, WhatsApp (rateado) | B17: =-Premissas!$B$34/Funil!$B$11 | C17: =0
A18: MARGEM LIQUIDA POR PEDIDO | B18: =$B$12+SUM(B14:B17) | C18: =$C$12+SUM(C14:C17)
A19: Margem liquida % | B19: =$B$18/$B$3 | C19: =$C$18/$C$3
A21: METAS — CAC e custo de produto compativeis com a margem alvo
A22: CAC maximo no breakeven | B22: =$B$12-$B$3*Premissas!$B$38*(Funil!$B$10/Funil!$B$11)-(Premissas!$B$37+Premissas!$B$34)/Funil!$B$11
A23: CAC maximo com 20% de margem liquida | B23: =$B$22-$B$3*0.2
A24: CAC atual do funil | B24: =Funil!$B$16
A25: Folga (CAC max na meta menos CAC atual) | B25: =$B$22-$B$3*Premissas!$B$46-Funil!$B$16 | D25: Negativo = o funil nao fecha no preco e custo atuais.
A26: Custo de produto MAXIMO dado o CAC atual | B26: =Custos!$D$18+$B$22-$B$3*Premissas!$B$46-Funil!$B$16 | D26: Alvo a levar para a negociacao com o fabricante, na margem meta.
A27: Custo de produto atual | B27: =Custos!$D$18
A29: RESULTADO MENSAL — VENDA DIRETA
A30: Pedidos pagos no mes | B30: =Funil!$B$11
A31: Receita bruta | B31: =B30*$B$3
A32: Margem liquida total | B32: =B30*$B$18
A33: Reserva rolante retida no mes | B33: =B31*Premissas!$B$54 | D33: Caixa retido pelo adquirente, tipicamente 6 meses. Nao e custo, mas trava capital de giro.
A35: No cenario de afiliado a comissao substitui a midia e o comercial nao atua — afiliado exige funil evergreen
A36: que roda sozinho. O webinar ao vivo das 20h nao porta para ClickBank como esta: primeiro voces provam a
A37: conversao com trafego proprio, depois transformam a melhor aula em VSL automatizado e so entao abrem a afiliados.

Sheet Oferta
A1: O QUE FAZER COM OS MESES 4 A 6 DO PO — preco de $389
A2: O brinde de 6 meses e a maior alavanca de custo do pedido. Aqui esta o efeito de encurta-lo.
B4: 1 — 3 meses de brinde, sem bump do po | C4: 2 — 3 meses + meses 4-6 no bump a $79 | D4: 3 — 3 meses + meses 4-6 no bump a $97
A5: Unid. do brinde incluidas gratis | B5: 3 | C5: 3 | D5: 3
A6: Preco do bump do po (meses 4-6) | B6: 0 | C6: 79 | D6: 97
A7: Take rate do bump do po | B7: 0 | C7: 0.4 | D7: 0.3
A9: Receita bruta por pedido | B9: =Premissas!$B$41+Premissas!$B$42*Premissas!$B$15+Premissas!$B$43*Premissas!$B$16+B6*B7 | C9: =Premissas!$B$41+Premissas!$B$42*Premissas!$B$15+Premissas!$B$43*Premissas!$B$16+C6*C7 | D9: =Premissas!$B$41+Premissas!$B$42*Premissas!$B$15+Premissas!$B$43*Premissas!$B$16+D6*D7
A10: Unidades fisicas enviadas | B10: =Premissas!$B$11+B5+B7*(6-B5)+Premissas!$B$13*Premissas!$B$15+Premissas!$B$14*Premissas!$B$16 | C10: =Premissas!$B$11+C5+C7*(6-C5)+Premissas!$B$13*Premissas!$B$15+Premissas!$B$14*Premissas!$B$16 | D10: =Premissas!$B$11+D5+D7*(6-D5)+Premissas!$B$13*Premissas!$B$15+Premissas!$B$14*Premissas!$B$16
A11: Custo do produto por pedido | B11: =Premissas!$B$11*Premissas!$B$4+B5*Premissas!$B$5+B7*(6-B5)*Premissas!$B$5+B10*Premissas!$B$8+Custos!$D$15 | C11: =Premissas!$B$11*Premissas!$B$4+C5*Premissas!$B$5+C7*(6-C5)*Premissas!$B$5+C10*Premissas!$B$8+Custos!$D$15 | D11: =Premissas!$B$11*Premissas!$B$4+D5*Premissas!$B$5+D7*(6-D5)*Premissas!$B$5+D10*Premissas!$B$8+Custos!$D$15
A12: Frete ao cliente | B12: =Premissas!$B$21+B10*Premissas!$B$22 | C12: =Premissas!$B$21+C10*Premissas!$B$22 | D12: =Premissas!$B$21+D10*Premissas!$B$22
A13: Outros custos de entrega | B13: =Premissas!$B$19+Premissas!$B$20+Premissas!$B$23+Premissas!$B$24 | C13: =Premissas!$B$19+Premissas!$B$20+Premissas!$B$23+Premissas!$B$24 | D13: =Premissas!$B$19+Premissas!$B$20+Premissas!$B$23+Premissas!$B$24
A14: Perdas (reembolso + chargeback) | B14: =B9*(Premissas!$B$51+Premissas!$B$52)+Premissas!$B$53*Premissas!$B$52 | C14: =C9*(Premissas!$B$51+Premissas!$B$52)+Premissas!$B$53*Premissas!$B$52 | D14: =D9*(Premissas!$B$51+Premissas!$B$52)+Premissas!$B$53*Premissas!$B$52
A15: Processamento | B15: =B9*Premissas!$B$49+Premissas!$B$50 | C15: =C9*Premissas!$B$49+Premissas!$B$50 | D15: =D9*Premissas!$B$49+Premissas!$B$50
A16: (=) Margem de contribuicao | B16: =B9-B11-B12-B13-B14-B15 | C16: =C9-C11-C12-C13-C14-C15 | D16: =D9-D11-D12-D13-D14-D15
A18: Produto como % da receita | B18: =B11/B9 | C18: =C11/C9 | D18: =D11/D9 | E18: Alvo do mercado: 20-25%.
A19: CAC maximo na margem alvo | B19: =B16-B9*Premissas!$B$46-B9*Premissas!$B$38*(Funil!$B$10/Funil!$B$11)-(Premissas!$B$37+Premissas!$B$34)/Funil!$B$11 | C19: =C16-C9*Premissas!$B$46-C9*Premissas!$B$38*(Funil!$B$10/Funil!$B$11)-(Premissas!$B$37+Premissas!$B$34)/Funil!$B$11 | D19: =D16-D9*Premissas!$B$46-D9*Premissas!$B$38*(Funil!$B$10/Funil!$B$11)-(Premissas!$B$37+Premissas!$B$34)/Funil!$B$11 | E19: Quanto voces podem pagar por pedido e ainda bater a margem alvo.
A20: CAC atual do funil | B20: =Funil!$B$16 | C20: =Funil!$B$16 | D20: =Funil!$B$16
A21: Folga | B21: =B19-B20 | C21: =C19-C20 | D21: =D19-D20
A22: Viavel? | B22: =IF(B21>=0,"SIM","NAO") | C22: =IF(C21>=0,"SIM","NAO") | D22: =IF(D21>=0,"SIM","NAO")
A25: LEITURA
A26: Config 1 — os 3 meses restantes simplesmente nao existem na oferta. E a mais simples de comunicar
A27: no pitch e a que gera menos receita. O po acaba no mes 3 e a cliente segue 3 meses so com o principal.
A29: Config 2 — os meses 4 a 6 do po viram bump de $79 no checkout. Mantem o protocolo completo disponivel,
A30: cria receita onde antes havia custo, e o argumento de venda e natural: 'complete o protocolo'.
A32: Config 3 — mesmo desenho a $97. Take rate tende a cair, mas a receita por pedido pode compensar.
A33: Testar os dois precos no checkout e barato e resolve a duvida em duas semanas de trafego.
A35: Recomendacao: Config 2. Os 3 meses gratis cobrem com folga a janela em que o po faz o trabalho de gerar
A36: resultado visivel e segurar a cliente no protocolo, e o bump recupera parte do custo sem tirar nada de
A37: quem nao quiser comprar. Compare a linha FOLGA nas tres colunas antes de decidir.

Sheet Teto_COGS
A1: TETO DE CUSTO DO PRODUTO
A2: Dado o preco e a margem desejada, quanto o produto PODE custar — e se a formula com dose clinica cabe.
A4: Margem liquida alvo (vem de PREMISSAS) | B4: =Premissas!$B$46
A6: Preco 6 meses | B6: Receita/pedido | C6: Custo max. do produto | D6: Custo max. por unidade | E6: Custo atual | F6: Cabe?
A7: 294 | B7: =A7+Premissas!$B$42*Premissas!$B$15+Premissas!$B$43*Premissas!$B$16+Premissas!$B$44*Premissas!$B$45 | C7: =B7*(1-Premissas!$B$51-Premissas!$B$52)-Premissas!$B$53*Premissas!$B$52-(B7*Premissas!$B$49+Premissas!$B$50)-(Custos!$D$24-Custos!$D$18)-Funil!$B$16-B7*Premissas!$B$38*(Funil!$B$10/Funil!$B$11)-(Premissas!$B$37+Premissas!$B$34)/Funil!$B$11-B7*$B$4 | D7: =IFERROR(C7/Custos!$B$8,0) | E7: =Custos!$D$18 | F7: =IF(C7>=E7,"SIM","NAO")
A8: 340 | B8: =A8+Premissas!$B$42*Premissas!$B$15+Premissas!$B$43*Premissas!$B$16+Premissas!$B$44*Premissas!$B$45 | C8: =B8*(1-Premissas!$B$51-Premissas!$B$52)-Premissas!$B$53*Premissas!$B$52-(B8*Premissas!$B$49+Premissas!$B$50)-(Custos!$D$24-Custos!$D$18)-Funil!$B$16-B8*Premissas!$B$38*(Funil!$B$10/Funil!$B$11)-(Premissas!$B$37+Premissas!$B$34)/Funil!$B$11-B8*$B$4 | D8: =IFERROR(C8/Custos!$B$8,0) | E8: =Custos!$D$18 | F8: =IF(C8>=E8,"SIM","NAO")
A9: 389 | B9: =A9+Premissas!$B$42*Premissas!$B$15+Premissas!$B$43*Premissas!$B$16+Premissas!$B$44*Premissas!$B$45 | C9: =B9*(1-Premissas!$B$51-Premissas!$B$52)-Premissas!$B$53*Premissas!$B$52-(B9*Premissas!$B$49+Premissas!$B$50)-(Custos!$D$24-Custos!$D$18)-Funil!$B$16-B9*Premissas!$B$38*(Funil!$B$10/Funil!$B$11)-(Premissas!$B$37+Premissas!$B$34)/Funil!$B$11-B9*$B$4 | D9: =IFERROR(C9/Custos!$B$8,0) | E9: =Custos!$D$18 | F9: =IF(C9>=E9,"SIM","NAO")
A10: 440 | B10: =A10+Premissas!$B$42*Premissas!$B$15+Premissas!$B$43*Premissas!$B$16+Premissas!$B$44*Premissas!$B$45 | C10: =B10*(1-Premissas!$B$51-Premissas!$B$52)-Premissas!$B$53*Premissas!$B$52-(B10*Premissas!$B$49+Premissas!$B$50)-(Custos!$D$24-Custos!$D$18)-Funil!$B$16-B10*Premissas!$B$38*(Funil!$B$10/Funil!$B$11)-(Premissas!$B$37+Premissas!$B$34)/Funil!$B$11-B10*$B$4 | D10: =IFERROR(C10/Custos!$B$8,0) | E10: =Custos!$D$18 | F10: =IF(C10>=E10,"SIM","NAO")
A11: 497 | B11: =A11+Premissas!$B$42*Premissas!$B$15+Premissas!$B$43*Premissas!$B$16+Premissas!$B$44*Premissas!$B$45 | C11: =B11*(1-Premissas!$B$51-Premissas!$B$52)-Premissas!$B$53*Premissas!$B$52-(B11*Premissas!$B$49+Premissas!$B$50)-(Custos!$D$24-Custos!$D$18)-Funil!$B$16-B11*Premissas!$B$38*(Funil!$B$10/Funil!$B$11)-(Premissas!$B$37+Premissas!$B$34)/Funil!$B$11-B11*$B$4 | D11: =IFERROR(C11/Custos!$B$8,0) | E11: =Custos!$D$18 | F11: =IF(C11>=E11,"SIM","NAO")
A12: 597 | B12: =A12+Premissas!$B$42*Premissas!$B$15+Premissas!$B$43*Premissas!$B$16+Premissas!$B$44*Premissas!$B$45 | C12: =B12*(1-Premissas!$B$51-Premissas!$B$52)-Premissas!$B$53*Premissas!$B$52-(B12*Premissas!$B$49+Premissas!$B$50)-(Custos!$D$24-Custos!$D$18)-Funil!$B$16-B12*Premissas!$B$38*(Funil!$B$10/Funil!$B$11)-(Premissas!$B$37+Premissas!$B$34)/Funil!$B$11-B12*$B$4 | D12: =IFERROR(C12/Custos!$B$8,0) | E12: =Custos!$D$18 | F12: =IF(C12>=E12,"SIM","NAO")
A14: Coluna A editavel. O primeiro preco com SIM e o piso de viabilidade da formula nos custos atuais.
A15: Se $389 aparece como NAO, ha tres saidas: encurtar o brinde (aba OFERTA), reduzir o custo do principal
A16: na cotacao, ou baixar o CAC melhorando conversao e CPL. Subir o preco e a quarta, que voces descartaram.

Sheet Precos
A1: ESCADA DE PRECOS
B3: 1 mes | C3: 3 meses | D3: 6 meses
A4: Preco da escada | B4: 89 | C4: 229 | D4: 389
A5: Meses | B5: 1 | C5: 3 | D5: 6
A6: Preco por mes | B6: =B4/B5 | C6: =C4/C5 | D6: =D4/D5
A7: Desconto vs. 1 mes | B7: =1-(B4/B5)/($B$4/$B$5) | C7: =1-(C4/C5)/($B$4/$B$5) | D7: =1-(D4/D5)/($B$4/$B$5)
A9: A escada existe para ancorar: o preco de 1 mes faz o de 6 meses parecer barato. Com $89 no mes avulso,
A10: a oferta de $389 por 6 meses mostra ~27% de desconto por mes — desconto suficiente para justificar a
A11: compra maior sem canibalizar a percepcao de valor do produto.
A13: No webinar ao vivo com fechamento humano, o padrao e apresentar SOMENTE a oferta de 6 meses no pitch e
A14: guardar 1 e 3 meses como alternativa de contorno de objecao na mao do comercial — nao como opcao na tela.
A15: Colocar as tres na tela derruba o ticket medio, porque a cliente escolhe a menor.

Sheet Grade
A1: GRADE DE VIABILIDADE — custo do principal x CAC
A2: Margem liquida resultante. Verde = bate a margem alvo. Tudo vem de PREMISSAS.
A3: Margem liquida alvo | B3: =Premissas!$B$46
A5: COMPONENTES FIXOS DO PEDIDO (nao dependem do custo do principal nem do CAC)
A6: Unidades enviadas por pedido | B6: =Premissas!$B$11+Premissas!$B$12+Premissas!$B$45*(Premissas!$B$11-Premissas!$B$12)+Premissas!$B$13*Premissas!$B$15+Premissas!$B$14*Premissas!$B$16
A7: Receita bruta por pedido | B7: =Premissas!$B$41+Premissas!$B$42*Premissas!$B$15+Premissas!$B$43*Premissas!$B$16+Premissas!$B$44*Premissas!$B$45
A8: Frete ao cliente | B8: =Premissas!$B$21+$B$6*Premissas!$B$22
A9: Outros custos de entrega | B9: =Premissas!$B$19+Premissas!$B$20+Premissas!$B$23+Premissas!$B$24
A10: Perdas (reembolso + chargeback) | B10: =$B$7*(Premissas!$B$51+Premissas!$B$52)+Premissas!$B$53*Premissas!$B$52
A11: Processamento | B11: =$B$7*Premissas!$B$49+Premissas!$B$50
A12: Comissao do comercial | B12: =$B$7*Premissas!$B$38*(Funil!$B$10/Funil!$B$11)
A13: Custo dos bumps (glicemico + acelerador) | B13: =Custos!$D$15
A14: Brinde (po) + frete de entrada do pacote | B14: =Premissas!$B$12*Premissas!$B$5+Premissas!$B$45*(Premissas!$B$11-Premissas!$B$12)*Premissas!$B$5+(Premissas!$B$11+Premissas!$B$12+Premissas!$B$45*(Premissas!$B$11-Premissas!$B$12))*Premissas!$B$8
A16: MARGEM LIQUIDA RESULTANTE
A17: Custo do principal \ CAC | B17: 60 | C17: 70 | D17: 80 | E17: 90 | F17: 100 | G17: 110 | H17: 120 | I17: 130 | J17: 140
A18: 6 | B18: =($B$7-(Premissas!$B$11*$A18+$B$14+$B$13)-$B$8-$B$9-$B$10-$B$11-B$17-$B$12-(Premissas!$B$37+Premissas!$B$34)*B$17/Premissas!$B$27)/$B$7 | C18: =($B$7-(Premissas!$B$11*$A18+$B$14+$B$13)-$B$8-$B$9-$B$10-$B$11-C$17-$B$12-(Premissas!$B$37+Premissas!$B$34)*C$17/Premissas!$B$27)/$B$7 | D18: =($B$7-(Premissas!$B$11*$A18+$B$14+$B$13)-$B$8-$B$9-$B$10-$B$11-D$17-$B$12-(Premissas!$B$37+Premissas!$B$34)*D$17/Premissas!$B$27)/$B$7 | E18: =($B$7-(Premissas!$B$11*$A18+$B$14+$B$13)-$B$8-$B$9-$B$10-$B$11-E$17-$B$12-(Premissas!$B$37+Premissas!$B$34)*E$17/Premissas!$B$27)/$B$7 | F18: =($B$7-(Premissas!$B$11*$A18+$B$14+$B$13)-$B$8-$B$9-$B$10-$B$11-F$17-$B$12-(Premissas!$B$37+Premissas!$B$34)*F$17/Premissas!$B$27)/$B$7 | G18: =($B$7-(Premissas!$B$11*$A18+$B$14+$B$13)-$B$8-$B$9-$B$10-$B$11-G$17-$B$12-(Premissas!$B$37+Premissas!$B$34)*G$17/Premissas!$B$27)/$B$7 | H18: =($B$7-(Premissas!$B$11*$A18+$B$14+$B$13)-$B$8-$B$9-$B$10-$B$11-H$17-$B$12-(Premissas!$B$37+Premissas!$B$34)*H$17/Premissas!$B$27)/$B$7 | I18: =($B$7-(Premissas!$B$11*$A18+$B$14+$B$13)-$B$8-$B$9-$B$10-$B$11-I$17-$B$12-(Premissas!$B$37+Premissas!$B$34)*I$17/Premissas!$B$27)/$B$7 | J18: =($B$7-(Premissas!$B$11*$A18+$B$14+$B$13)-$B$8-$B$9-$B$10-$B$11-J$17-$B$12-(Premissas!$B$37+Premissas!$B$34)*J$17/Premissas!$B$27)/$B$7 | M18: Linhas e colunas sao editaveis.
A19: 7 | B19: =($B$7-(Premissas!$B$11*$A19+$B$14+$B$13)-$B$8-$B$9-$B$10-$B$11-B$17-$B$12-(Premissas!$B$37+Premissas!$B$34)*B$17/Premissas!$B$27)/$B$7 | C19: =($B$7-(Premissas!$B$11*$A19+$B$14+$B$13)-$B$8-$B$9-$B$10-$B$11-C$17-$B$12-(Premissas!$B$37+Premissas!$B$34)*C$17/Premissas!$B$27)/$B$7 | D19: =($B$7-(Premissas!$B$11*$A19+$B$14+$B$13)-$B$8-$B$9-$B$10-$B$11-D$17-$B$12-(Premissas!$B$37+Premissas!$B$34)*D$17/Premissas!$B$27)/$B$7 | E19: =($B$7-(Premissas!$B$11*$A19+$B$14+$B$13)-$B$8-$B$9-$B$10-$B$11-E$17-$B$12-(Premissas!$B$37+Premissas!$B$34)*E$17/Premissas!$B$27)/$B$7 | F19: =($B$7-(Premissas!$B$11*$A19+$B$14+$B$13)-$B$8-$B$9-$B$10-$B$11-F$17-$B$12-(Premissas!$B$37+Premissas!$B$34)*F$17/Premissas!$B$27)/$B$7 | G19: =($B$7-(Premissas!$B$11*$A19+$B$14+$B$13)-$B$8-$B$9-$B$10-$B$11-G$17-$B$12-(Premissas!$B$37+Premissas!$B$34)*G$17/Premissas!$B$27)/$B$7 | H19: =($B$7-(Premissas!$B$11*$A19+$B$14+$B$13)-$B$8-$B$9-$B$10-$B$11-H$17-$B$12-(Premissas!$B$37+Premissas!$B$34)*H$17/Premissas!$B$27)/$B$7 | I19: =($B$7-(Premissas!$B$11*$A19+$B$14+$B$13)-$B$8-$B$9-$B$10-$B$11-I$17-$B$12-(Premissas!$B$37+Premissas!$B$34)*I$17/Premissas!$B$27)/$B$7 | J19: =($B$7-(Premissas!$B$11*$A19+$B$14+$B$13)-$B$8-$B$9-$B$10-$B$11-J$17-$B$12-(Premissas!$B$37+Premissas!$B$34)*J$17/Premissas!$B$27)/$B$7 | M19: Verde = bate a margem alvo.
A20: 8 | B20: =($B$7-(Premissas!$B$11*$A20+$B$14+$B$13)-$B$8-$B$9-$B$10-$B$11-B$17-$B$12-(Premissas!$B$37+Premissas!$B$34)*B$17/Premissas!$B$27)/$B$7 | C20: =($B$7-(Premissas!$B$11*$A20+$B$14+$B$13)-$B$8-$B$9-$B$10-$B$11-C$17-$B$12-(Premissas!$B$37+Premissas!$B$34)*C$17/Premissas!$B$27)/$B$7 | D20: =($B$7-(Premissas!$B$11*$A20+$B$14+$B$13)-$B$8-$B$9-$B$10-$B$11-D$17-$B$12-(Premissas!$B$37+Premissas!$B$34)*D$17/Premissas!$B$27)/$B$7 | E20: =($B$7-(Premissas!$B$11*$A20+$B$14+$B$13)-$B$8-$B$9-$B$10-$B$11-E$17-$B$12-(Premissas!$B$37+Premissas!$B$34)*E$17/Premissas!$B$27)/$B$7 | F20: =($B$7-(Premissas!$B$11*$A20+$B$14+$B$13)-$B$8-$B$9-$B$10-$B$11-F$17-$B$12-(Premissas!$B$37+Premissas!$B$34)*F$17/Premissas!$B$27)/$B$7 | G20: =($B$7-(Premissas!$B$11*$A20+$B$14+$B$13)-$B$8-$B$9-$B$10-$B$11-G$17-$B$12-(Premissas!$B$37+Premissas!$B$34)*G$17/Premissas!$B$27)/$B$7 | H20: =($B$7-(Premissas!$B$11*$A20+$B$14+$B$13)-$B$8-$B$9-$B$10-$B$11-H$17-$B$12-(Premissas!$B$37+Premissas!$B$34)*H$17/Premissas!$B$27)/$B$7 | I20: =($B$7-(Premissas!$B$11*$A20+$B$14+$B$13)-$B$8-$B$9-$B$10-$B$11-I$17-$B$12-(Premissas!$B$37+Premissas!$B$34)*I$17/Premissas!$B$27)/$B$7 | J20: =($B$7-(Premissas!$B$11*$A20+$B$14+$B$13)-$B$8-$B$9-$B$10-$B$11-J$17-$B$12-(Premissas!$B$37+Premissas!$B$34)*J$17/Premissas!$B$27)/$B$7 | M20: Vermelho = prejuizo por pedido.
A21: 9 | B21: =($B$7-(Premissas!$B$11*$A21+$B$14+$B$13)-$B$8-$B$9-$B$10-$B$11-B$17-$B$12-(Premissas!$B$37+Premissas!$B$34)*B$17/Premissas!$B$27)/$B$7 | C21: =($B$7-(Premissas!$B$11*$A21+$B$14+$B$13)-$B$8-$B$9-$B$10-$B$11-C$17-$B$12-(Premissas!$B$37+Premissas!$B$34)*C$17/Premissas!$B$27)/$B$7 | D21: =($B$7-(Premissas!$B$11*$A21+$B$14+$B$13)-$B$8-$B$9-$B$10-$B$11-D$17-$B$12-(Premissas!$B$37+Premissas!$B$34)*D$17/Premissas!$B$27)/$B$7 | E21: =($B$7-(Premissas!$B$11*$A21+$B$14+$B$13)-$B$8-$B$9-$B$10-$B$11-E$17-$B$12-(Premissas!$B$37+Premissas!$B$34)*E$17/Premissas!$B$27)/$B$7 | F21: =($B$7-(Premissas!$B$11*$A21+$B$14+$B$13)-$B$8-$B$9-$B$10-$B$11-F$17-$B$12-(Premissas!$B$37+Premissas!$B$34)*F$17/Premissas!$B$27)/$B$7 | G21: =($B$7-(Premissas!$B$11*$A21+$B$14+$B$13)-$B$8-$B$9-$B$10-$B$11-G$17-$B$12-(Premissas!$B$37+Premissas!$B$34)*G$17/Premissas!$B$27)/$B$7 | H21: =($B$7-(Premissas!$B$11*$A21+$B$14+$B$13)-$B$8-$B$9-$B$10-$B$11-H$17-$B$12-(Premissas!$B$37+Premissas!$B$34)*H$17/Premissas!$B$27)/$B$7 | I21: =($B$7-(Premissas!$B$11*$A21+$B$14+$B$13)-$B$8-$B$9-$B$10-$B$11-I$17-$B$12-(Premissas!$B$37+Premissas!$B$34)*I$17/Premissas!$B$27)/$B$7 | J21: =($B$7-(Premissas!$B$11*$A21+$B$14+$B$13)-$B$8-$B$9-$B$10-$B$11-J$17-$B$12-(Premissas!$B$37+Premissas!$B$34)*J$17/Premissas!$B$27)/$B$7
A22: 10 | B22: =($B$7-(Premissas!$B$11*$A22+$B$14+$B$13)-$B$8-$B$9-$B$10-$B$11-B$17-$B$12-(Premissas!$B$37+Premissas!$B$34)*B$17/Premissas!$B$27)/$B$7 | C22: =($B$7-(Premissas!$B$11*$A22+$B$14+$B$13)-$B$8-$B$9-$B$10-$B$11-C$17-$B$12-(Premissas!$B$37+Premissas!$B$34)*C$17/Premissas!$B$27)/$B$7 | D22: =($B$7-(Premissas!$B$11*$A22+$B$14+$B$13)-$B$8-$B$9-$B$10-$B$11-D$17-$B$12-(Premissas!$B$37+Premissas!$B$34)*D$17/Premissas!$B$27)/$B$7 | E22: =($B$7-(Premissas!$B$11*$A22+$B$14+$B$13)-$B$8-$B$9-$B$10-$B$11-E$17-$B$12-(Premissas!$B$37+Premissas!$B$34)*E$17/Premissas!$B$27)/$B$7 | F22: =($B$7-(Premissas!$B$11*$A22+$B$14+$B$13)-$B$8-$B$9-$B$10-$B$11-F$17-$B$12-(Premissas!$B$37+Premissas!$B$34)*F$17/Premissas!$B$27)/$B$7 | G22: =($B$7-(Premissas!$B$11*$A22+$B$14+$B$13)-$B$8-$B$9-$B$10-$B$11-G$17-$B$12-(Premissas!$B$37+Premissas!$B$34)*G$17/Premissas!$B$27)/$B$7 | H22: =($B$7-(Premissas!$B$11*$A22+$B$14+$B$13)-$B$8-$B$9-$B$10-$B$11-H$17-$B$12-(Premissas!$B$37+Premissas!$B$34)*H$17/Premissas!$B$27)/$B$7 | I22: =($B$7-(Premissas!$B$11*$A22+$B$14+$B$13)-$B$8-$B$9-$B$10-$B$11-I$17-$B$12-(Premissas!$B$37+Premissas!$B$34)*I$17/Premissas!$B$27)/$B$7 | J22: =($B$7-(Premissas!$B$11*$A22+$B$14+$B$13)-$B$8-$B$9-$B$10-$B$11-J$17-$B$12-(Premissas!$B$37+Premissas!$B$34)*J$17/Premissas!$B$27)/$B$7 | M22: O CAC ja embute o rateio do custo fixo do
A23: 11 | B23: =($B$7-(Premissas!$B$11*$A23+$B$14+$B$13)-$B$8-$B$9-$B$10-$B$11-B$17-$B$12-(Premissas!$B$37+Premissas!$B$34)*B$17/Premissas!$B$27)/$B$7 | C23: =($B$7-(Premissas!$B$11*$A23+$B$14+$B$13)-$B$8-$B$9-$B$10-$B$11-C$17-$B$12-(Premissas!$B$37+Premissas!$B$34)*C$17/Premissas!$B$27)/$B$7 | D23: =($B$7-(Premissas!$B$11*$A23+$B$14+$B$13)-$B$8-$B$9-$B$10-$B$11-D$17-$B$12-(Premissas!$B$37+Premissas!$B$34)*D$17/Premissas!$B$27)/$B$7 | E23: =($B$7-(Premissas!$B$11*$A23+$B$14+$B$13)-$B$8-$B$9-$B$10-$B$11-E$17-$B$12-(Premissas!$B$37+Premissas!$B$34)*E$17/Premissas!$B$27)/$B$7 | F23: =($B$7-(Premissas!$B$11*$A23+$B$14+$B$13)-$B$8-$B$9-$B$10-$B$11-F$17-$B$12-(Premissas!$B$37+Premissas!$B$34)*F$17/Premissas!$B$27)/$B$7 | G23: =($B$7-(Premissas!$B$11*$A23+$B$14+$B$13)-$B$8-$B$9-$B$10-$B$11-G$17-$B$12-(Premissas!$B$37+Premissas!$B$34)*G$17/Premissas!$B$27)/$B$7 | H23: =($B$7-(Premissas!$B$11*$A23+$B$14+$B$13)-$B$8-$B$9-$B$10-$B$11-H$17-$B$12-(Premissas!$B$37+Premissas!$B$34)*H$17/Premissas!$B$27)/$B$7 | I23: =($B$7-(Premissas!$B$11*$A23+$B$14+$B$13)-$B$8-$B$9-$B$10-$B$11-I$17-$B$12-(Premissas!$B$37+Premissas!$B$34)*I$17/Premissas!$B$27)/$B$7 | J23: =($B$7-(Premissas!$B$11*$A23+$B$14+$B$13)-$B$8-$B$9-$B$10-$B$11-J$17-$B$12-(Premissas!$B$37+Premissas!$B$34)*J$17/Premissas!$B$27)/$B$7 | M23: comercial e do CRM: CAC menor significa mais
A24: 12 | B24: =($B$7-(Premissas!$B$11*$A24+$B$14+$B$13)-$B$8-$B$9-$B$10-$B$11-B$17-$B$12-(Premissas!$B$37+Premissas!$B$34)*B$17/Premissas!$B$27)/$B$7 | C24: =($B$7-(Premissas!$B$11*$A24+$B$14+$B$13)-$B$8-$B$9-$B$10-$B$11-C$17-$B$12-(Premissas!$B$37+Premissas!$B$34)*C$17/Premissas!$B$27)/$B$7 | D24: =($B$7-(Premissas!$B$11*$A24+$B$14+$B$13)-$B$8-$B$9-$B$10-$B$11-D$17-$B$12-(Premissas!$B$37+Premissas!$B$34)*D$17/Premissas!$B$27)/$B$7 | E24: =($B$7-(Premissas!$B$11*$A24+$B$14+$B$13)-$B$8-$B$9-$B$10-$B$11-E$17-$B$12-(Premissas!$B$37+Premissas!$B$34)*E$17/Premissas!$B$27)/$B$7 | F24: =($B$7-(Premissas!$B$11*$A24+$B$14+$B$13)-$B$8-$B$9-$B$10-$B$11-F$17-$B$12-(Premissas!$B$37+Premissas!$B$34)*F$17/Premissas!$B$27)/$B$7 | G24: =($B$7-(Premissas!$B$11*$A24+$B$14+$B$13)-$B$8-$B$9-$B$10-$B$11-G$17-$B$12-(Premissas!$B$37+Premissas!$B$34)*G$17/Premissas!$B$27)/$B$7 | H24: =($B$7-(Premissas!$B$11*$A24+$B$14+$B$13)-$B$8-$B$9-$B$10-$B$11-H$17-$B$12-(Premissas!$B$37+Premissas!$B$34)*H$17/Premissas!$B$27)/$B$7 | I24: =($B$7-(Premissas!$B$11*$A24+$B$14+$B$13)-$B$8-$B$9-$B$10-$B$11-I$17-$B$12-(Premissas!$B$37+Premissas!$B$34)*I$17/Premissas!$B$27)/$B$7 | J24: =($B$7-(Premissas!$B$11*$A24+$B$14+$B$13)-$B$8-$B$9-$B$10-$B$11-J$17-$B$12-(Premissas!$B$37+Premissas!$B$34)*J$17/Premissas!$B$27)/$B$7 | M24: pedidos, logo menos custo fixo por pedido.
A25: 13 | B25: =($B$7-(Premissas!$B$11*$A25+$B$14+$B$13)-$B$8-$B$9-$B$10-$B$11-B$17-$B$12-(Premissas!$B$37+Premissas!$B$34)*B$17/Premissas!$B$27)/$B$7 | C25: =($B$7-(Premissas!$B$11*$A25+$B$14+$B$13)-$B$8-$B$9-$B$10-$B$11-C$17-$B$12-(Premissas!$B$37+Premissas!$B$34)*C$17/Premissas!$B$27)/$B$7 | D25: =($B$7-(Premissas!$B$11*$A25+$B$14+$B$13)-$B$8-$B$9-$B$10-$B$11-D$17-$B$12-(Premissas!$B$37+Premissas!$B$34)*D$17/Premissas!$B$27)/$B$7 | E25: =($B$7-(Premissas!$B$11*$A25+$B$14+$B$13)-$B$8-$B$9-$B$10-$B$11-E$17-$B$12-(Premissas!$B$37+Premissas!$B$34)*E$17/Premissas!$B$27)/$B$7 | F25: =($B$7-(Premissas!$B$11*$A25+$B$14+$B$13)-$B$8-$B$9-$B$10-$B$11-F$17-$B$12-(Premissas!$B$37+Premissas!$B$34)*F$17/Premissas!$B$27)/$B$7 | G25: =($B$7-(Premissas!$B$11*$A25+$B$14+$B$13)-$B$8-$B$9-$B$10-$B$11-G$17-$B$12-(Premissas!$B$37+Premissas!$B$34)*G$17/Premissas!$B$27)/$B$7 | H25: =($B$7-(Premissas!$B$11*$A25+$B$14+$B$13)-$B$8-$B$9-$B$10-$B$11-H$17-$B$12-(Premissas!$B$37+Premissas!$B$34)*H$17/Premissas!$B$27)/$B$7 | I25: =($B$7-(Premissas!$B$11*$A25+$B$14+$B$13)-$B$8-$B$9-$B$10-$B$11-I$17-$B$12-(Premissas!$B$37+Premissas!$B$34)*I$17/Premissas!$B$27)/$B$7 | J25: =($B$7-(Premissas!$B$11*$A25+$B$14+$B$13)-$B$8-$B$9-$B$10-$B$11-J$17-$B$12-(Premissas!$B$37+Premissas!$B$34)*J$17/Premissas!$B$27)/$B$7
A26: 14 | B26: =($B$7-(Premissas!$B$11*$A26+$B$14+$B$13)-$B$8-$B$9-$B$10-$B$11-B$17-$B$12-(Premissas!$B$37+Premissas!$B$34)*B$17/Premissas!$B$27)/$B$7 | C26: =($B$7-(Premissas!$B$11*$A26+$B$14+$B$13)-$B$8-$B$9-$B$10-$B$11-C$17-$B$12-(Premissas!$B$37+Premissas!$B$34)*C$17/Premissas!$B$27)/$B$7 | D26: =($B$7-(Premissas!$B$11*$A26+$B$14+$B$13)-$B$8-$B$9-$B$10-$B$11-D$17-$B$12-(Premissas!$B$37+Premissas!$B$34)*D$17/Premissas!$B$27)/$B$7 | E26: =($B$7-(Premissas!$B$11*$A26+$B$14+$B$13)-$B$8-$B$9-$B$10-$B$11-E$17-$B$12-(Premissas!$B$37+Premissas!$B$34)*E$17/Premissas!$B$27)/$B$7 | F26: =($B$7-(Premissas!$B$11*$A26+$B$14+$B$13)-$B$8-$B$9-$B$10-$B$11-F$17-$B$12-(Premissas!$B$37+Premissas!$B$34)*F$17/Premissas!$B$27)/$B$7 | G26: =($B$7-(Premissas!$B$11*$A26+$B$14+$B$13)-$B$8-$B$9-$B$10-$B$11-G$17-$B$12-(Premissas!$B$37+Premissas!$B$34)*G$17/Premissas!$B$27)/$B$7 | H26: =($B$7-(Premissas!$B$11*$A26+$B$14+$B$13)-$B$8-$B$9-$B$10-$B$11-H$17-$B$12-(Premissas!$B$37+Premissas!$B$34)*H$17/Premissas!$B$27)/$B$7 | I26: =($B$7-(Premissas!$B$11*$A26+$B$14+$B$13)-$B$8-$B$9-$B$10-$B$11-I$17-$B$12-(Premissas!$B$37+Premissas!$B$34)*I$17/Premissas!$B$27)/$B$7 | J26: =($B$7-(Premissas!$B$11*$A26+$B$14+$B$13)-$B$8-$B$9-$B$10-$B$11-J$17-$B$12-(Premissas!$B$37+Premissas!$B$34)*J$17/Premissas!$B$27)/$B$7
A27: 15 | B27: =($B$7-(Premissas!$B$11*$A27+$B$14+$B$13)-$B$8-$B$9-$B$10-$B$11-B$17-$B$12-(Premissas!$B$37+Premissas!$B$34)*B$17/Premissas!$B$27)/$B$7 | C27: =($B$7-(Premissas!$B$11*$A27+$B$14+$B$13)-$B$8-$B$9-$B$10-$B$11-C$17-$B$12-(Premissas!$B$37+Premissas!$B$34)*C$17/Premissas!$B$27)/$B$7 | D27: =($B$7-(Premissas!$B$11*$A27+$B$14+$B$13)-$B$8-$B$9-$B$10-$B$11-D$17-$B$12-(Premissas!$B$37+Premissas!$B$34)*D$17/Premissas!$B$27)/$B$7 | E27: =($B$7-(Premissas!$B$11*$A27+$B$14+$B$13)-$B$8-$B$9-$B$10-$B$11-E$17-$B$12-(Premissas!$B$37+Premissas!$B$34)*E$17/Premissas!$B$27)/$B$7 | F27: =($B$7-(Premissas!$B$11*$A27+$B$14+$B$13)-$B$8-$B$9-$B$10-$B$11-F$17-$B$12-(Premissas!$B$37+Premissas!$B$34)*F$17/Premissas!$B$27)/$B$7 | G27: =($B$7-(Premissas!$B$11*$A27+$B$14+$B$13)-$B$8-$B$9-$B$10-$B$11-G$17-$B$12-(Premissas!$B$37+Premissas!$B$34)*G$17/Premissas!$B$27)/$B$7 | H27: =($B$7-(Premissas!$B$11*$A27+$B$14+$B$13)-$B$8-$B$9-$B$10-$B$11-H$17-$B$12-(Premissas!$B$37+Premissas!$B$34)*H$17/Premissas!$B$27)/$B$7 | I27: =($B$7-(Premissas!$B$11*$A27+$B$14+$B$13)-$B$8-$B$9-$B$10-$B$11-I$17-$B$12-(Premissas!$B$37+Premissas!$B$34)*I$17/Premissas!$B$27)/$B$7 | J27: =($B$7-(Premissas!$B$11*$A27+$B$14+$B$13)-$B$8-$B$9-$B$10-$B$11-J$17-$B$12-(Premissas!$B$37+Premissas!$B$34)*J$17/Premissas!$B$27)/$B$7
A28: 16 | B28: =($B$7-(Premissas!$B$11*$A28+$B$14+$B$13)-$B$8-$B$9-$B$10-$B$11-B$17-$B$12-(Premissas!$B$37+Premissas!$B$34)*B$17/Premissas!$B$27)/$B$7 | C28: =($B$7-(Premissas!$B$11*$A28+$B$14+$B$13)-$B$8-$B$9-$B$10-$B$11-C$17-$B$12-(Premissas!$B$37+Premissas!$B$34)*C$17/Premissas!$B$27)/$B$7 | D28: =($B$7-(Premissas!$B$11*$A28+$B$14+$B$13)-$B$8-$B$9-$B$10-$B$11-D$17-$B$12-(Premissas!$B$37+Premissas!$B$34)*D$17/Premissas!$B$27)/$B$7 | E28: =($B$7-(Premissas!$B$11*$A28+$B$14+$B$13)-$B$8-$B$9-$B$10-$B$11-E$17-$B$12-(Premissas!$B$37+Premissas!$B$34)*E$17/Premissas!$B$27)/$B$7 | F28: =($B$7-(Premissas!$B$11*$A28+$B$14+$B$13)-$B$8-$B$9-$B$10-$B$11-F$17-$B$12-(Premissas!$B$37+Premissas!$B$34)*F$17/Premissas!$B$27)/$B$7 | G28: =($B$7-(Premissas!$B$11*$A28+$B$14+$B$13)-$B$8-$B$9-$B$10-$B$11-G$17-$B$12-(Premissas!$B$37+Premissas!$B$34)*G$17/Premissas!$B$27)/$B$7 | H28: =($B$7-(Premissas!$B$11*$A28+$B$14+$B$13)-$B$8-$B$9-$B$10-$B$11-H$17-$B$12-(Premissas!$B$37+Premissas!$B$34)*H$17/Premissas!$B$27)/$B$7 | I28: =($B$7-(Premissas!$B$11*$A28+$B$14+$B$13)-$B$8-$B$9-$B$10-$B$11-I$17-$B$12-(Premissas!$B$37+Premissas!$B$34)*I$17/Premissas!$B$27)/$B$7 | J28: =($B$7-(Premissas!$B$11*$A28+$B$14+$B$13)-$B$8-$B$9-$B$10-$B$11-J$17-$B$12-(Premissas!$B$37+Premissas!$B$34)*J$17/Premissas!$B$27)/$B$7
A30: A ALAVANCA MENOS OLHADA — TAXA DE REEMBOLSO
A31: Taxa de reembolso | B31: 0.18 | C31: 0.15 | D31: 0.12 | E31: 0.09 | F31: 0.06 | G31: 0.04
A32: Perda por pedido | B32: =$B$7*B$31+Premissas!$B$53*Premissas!$B$52+$B$7*Premissas!$B$52 | C32: =$B$7*C$31+Premissas!$B$53*Premissas!$B$52+$B$7*Premissas!$B$52 | D32: =$B$7*D$31+Premissas!$B$53*Premissas!$B$52+$B$7*Premissas!$B$52 | E32: =$B$7*E$31+Premissas!$B$53*Premissas!$B$52+$B$7*Premissas!$B$52 | F32: =$B$7*F$31+Premissas!$B$53*Premissas!$B$52+$B$7*Premissas!$B$52 | G32: =$B$7*G$31+Premissas!$B$53*Premissas!$B$52+$B$7*Premissas!$B$52
A33: Margem no custo e CAC atuais | B33: =($B$7-(Premissas!$B$11*Premissas!$B$4+$B$14+$B$13)-$B$8-$B$9-($B$7*(B$31+Premissas!$B$52)+Premissas!$B$53*Premissas!$B$52)-$B$11-Funil!$B$16-$B$12-(Premissas!$B$37+Premissas!$B$34)/Funil!$B$11)/$B$7 | C33: =($B$7-(Premissas!$B$11*Premissas!$B$4+$B$14+$B$13)-$B$8-$B$9-($B$7*(C$31+Premissas!$B$52)+Premissas!$B$53*Premissas!$B$52)-$B$11-Funil!$B$16-$B$12-(Premissas!$B$37+Premissas!$B$34)/Funil!$B$11)/$B$7 | D33: =($B$7-(Premissas!$B$11*Premissas!$B$4+$B$14+$B$13)-$B$8-$B$9-($B$7*(D$31+Premissas!$B$52)+Premissas!$B$53*Premissas!$B$52)-$B$11-Funil!$B$16-$B$12-(Premissas!$B$37+Premissas!$B$34)/Funil!$B$11)/$B$7 | E33: =($B$7-(Premissas!$B$11*Premissas!$B$4+$B$14+$B$13)-$B$8-$B$9-($B$7*(E$31+Premissas!$B$52)+Premissas!$B$53*Premissas!$B$52)-$B$11-Funil!$B$16-$B$12-(Premissas!$B$37+Premissas!$B$34)/Funil!$B$11)/$B$7 | F33: =($B$7-(Premissas!$B$11*Premissas!$B$4+$B$14+$B$13)-$B$8-$B$9-($B$7*(F$31+Premissas!$B$52)+Premissas!$B$53*Premissas!$B$52)-$B$11-Funil!$B$16-$B$12-(Premissas!$B$37+Premissas!$B$34)/Funil!$B$11)/$B$7 | G33: =($B$7-(Premissas!$B$11*Premissas!$B$4+$B$14+$B$13)-$B$8-$B$9-($B$7*(G$31+Premissas!$B$52)+Premissas!$B$53*Premissas!$B$52)-$B$11-Funil!$B$16-$B$12-(Premissas!$B$37+Premissas!$B$34)/Funil!$B$11)/$B$7
A35: Reembolso e o segundo maior custo do pedido, maior que frete, 3PL, embalagem e processamento somados.
A36: Cair de 12% para 9% vale cerca de 3 pontos de margem — o mesmo que cortar $2 do custo do frasco.
A37: As alavancas sao: garantia desenhada para devolucao de frascos lacrados, expectativa correta no pitch,
A38: onboarding nas primeiras duas semanas e o proprio comercial acompanhando quem comprou.

Sheet Target
A1: TARGET DE CUSTO POR PRODUTO — para levar ao fornecedor
A2: Derivado de tras para frente: preco de venda, margem alvo e CAC definem quanto o produto pode custar.
A3: Todos os targets sao FOB fabricante, com frasco e rotulo. Frete de entrada esta em linha separada.
A5: 1. ORCAMENTO DE PRODUTO POR PEDIDO
A6: Receita bruta por pedido | B6: =Premissas!$B$41+Premissas!$B$42*Premissas!$B$15+Premissas!$B$43*Premissas!$B$16+Premissas!$B$44*Premissas!$B$45
A7: Unidades enviadas por pedido | B7: =Premissas!$B$11+Premissas!$B$12+Premissas!$B$45*(Premissas!$B$11-Premissas!$B$12)+Premissas!$B$13*Premissas!$B$15+Premissas!$B$14*Premissas!$B$16
A8: (-) Frete ao cliente | B8: =-(Premissas!$B$21+$B$7*Premissas!$B$22)
A9: (-) Caixa, 3PL, armazenagem, suporte | B9: =-(Premissas!$B$19+Premissas!$B$20+Premissas!$B$23+Premissas!$B$24)
A10: (-) Reembolso e chargeback | B10: =-($B$6*(Premissas!$B$51+Premissas!$B$52)+Premissas!$B$53*Premissas!$B$52)
A11: (-) Processamento | B11: =-($B$6*Premissas!$B$49+Premissas!$B$50)
A12: (-) Comissao do comercial | B12: =-($B$6*Premissas!$B$38*(Funil!$B$10/Funil!$B$11))
A13: (-) CAC de planejamento | B13: -90 | D13: EDITAR. Negativo. E a premissa que mais mexe no target.
A14: (-) Rateio do fixo comercial e CRM | B14: =(Premissas!$B$37+Premissas!$B$34)*$B$13/Premissas!$B$27
A15: (-) Margem liquida alvo | B15: =-$B$6*Premissas!$B$46
A16: ORCAMENTO DE PRODUTO POR PEDIDO | B16: =$B$6+SUM(B8:B15)
A18: 2. ALOCACAO POR SKU
A19: SKU | B19: Unid./pedido | C19: Target unitario | D19: Custo no pedido
A20: Brinde — po (30 dias) | B20: =Premissas!$B$12+Premissas!$B$45*(Premissas!$B$11-Premissas!$B$12) | C20: 5 | D20: =B20*C20 | F20: Glucomanan e barato em bulk; o pote pesa mais que o custo.
A21: Bump Glicemico (60 caps) | B21: =Premissas!$B$13*Premissas!$B$15 | C21: 4 | D21: =B21*C21 | F21: Gymnema, cromo, canela, ALA — todos commodity.
A22: Bump Acelerador (60 caps) | B22: =Premissas!$B$14*Premissas!$B$16 | C22: 4.5 | D22: =B22*C22 | F22: Capsimax e licenciado; o resto e commodity.
A23: Frete de entrada (todas as unidades) | B23: =$B$7 | C23: =Premissas!$B$8 | D23: =B23*C23
A24: Subtotal (tudo menos o principal) | D24: =SUM(D20:D23)
A26: 3. TARGET DO PRODUTO PRINCIPAL (o que sobra do orcamento)
A27: Orcamento disponivel para o principal | B27: =$B$16-$D$24
A28: Unidades do principal por pedido | B28: =Premissas!$B$11
A29: TARGET POR FRASCO DO PRINCIPAL | B29: =$B$27/Premissas!$B$11 | D29: Numero para levar ao fornecedor. Arredonde para baixo na negociacao.
A31: Cada $1 a menos no frasco do principal vale, no pedido: | B31: =Premissas!$B$11 | D31: Sao 6 frascos por cliente: negociar o principal vale 6x mais que qualquer outro SKU.
A33: 4. TARGET DO PRINCIPAL POR CENARIO DE CAC
A34: CAC de planejamento | B34: 70 | C34: 75 | D34: 80 | E34: 90 | F34: 100 | G34: 110
A35: Orcamento de produto no pedido | B35: =$B$16-$B$13-$B$14-B$34*(1+(Premissas!$B$37+Premissas!$B$34)/Premissas!$B$27) | C35: =$B$16-$B$13-$B$14-C$34*(1+(Premissas!$B$37+Premissas!$B$34)/Premissas!$B$27) | D35: =$B$16-$B$13-$B$14-D$34*(1+(Premissas!$B$37+Premissas!$B$34)/Premissas!$B$27) | E35: =$B$16-$B$13-$B$14-E$34*(1+(Premissas!$B$37+Premissas!$B$34)/Premissas!$B$27) | F35: =$B$16-$B$13-$B$14-F$34*(1+(Premissas!$B$37+Premissas!$B$34)/Premissas!$B$27) | G35: =$B$16-$B$13-$B$14-G$34*(1+(Premissas!$B$37+Premissas!$B$34)/Premissas!$B$27)
A36: TARGET POR FRASCO DO PRINCIPAL | B36: =(B35-$D$24)/Premissas!$B$11 | C36: =(C35-$D$24)/Premissas!$B$11 | D36: =(D35-$D$24)/Premissas!$B$11 | E36: =(E35-$D$24)/Premissas!$B$11 | F36: =(F35-$D$24)/Premissas!$B$11 | G36: =(G35-$D$24)/Premissas!$B$11
A38: 5. O QUE O TARGET IMPLICA NA FORMULA
A39: O target do principal nao e so um numero de negociacao: ele decide a formula. Uma estimativa de mercado dos
A40: quatro ativos do briefing, em dose clinica, por frasco de 30 dias:
A42: Satiereal (acafrao) 176 mg/dia ...... o mais caro dos quatro, possivelmente metade do custo do frasco
A43: Morosil (laranja moro) 400 mg/dia ... segundo maior
A44: Slendesta (proteina de batata) 300 mg moderado
A45: Berberina HCl 1.000 mg/dia .......... barato; di-hidroberberina custa varias vezes mais
A46: Encapsulacao, frasco, rotulo ........ fixo, baixo
A48: Conclusao pratica: se o target ficar abaixo de $10 por frasco, a formula completa do briefing dificilmente cabe.
...
